# DeepDive #47장 에러 처리

![Uploading common-windows-xp-error-messages-and-fix.jpg…]()

# 47장 에러 처리

## 47.1 에러 처리의 필요성

에러가 발생하지 않는 코드를 작성하는 것은 불가능하다. 따라서 에러는 언제나 발생할 수 있다. 발생한 에러에 대해 대처하지 않고 방치하면 프로그램은 종료된다.

```jsx
console.log('[Start]');

foo(); // ReferenceError: foo is not defined
// 발생한 에러를 방치하면 프로그램은 강제 종료된다.

// 에러에 의해 프로그램이 강제 종료되어 아래 코드는 실행되지 않는다.
console.log('[End]');
```

try ... catch 문을 사용해 발생한 에러에 적절하게 대응하면 프로그램이 강제 종료되지 않고 계속해서 코드를 실행시킬 수 있다.

```jsx
console.log('[Start]');

try {
  foo();
} catch (error) {
  console.error('[에러 발생]', error);
  // [에러 발생] ReferenceError: foo is not defined
}

// 발생한 에러에 적절한 대응을 하면 프로그램이 강제 종료되지 않는다.
console.log('[End]');
```

직접적으로 에러를 발생하지는 않는 예외적인 상황이 발생할 수도 잇다. 예외적인 상황에 적절하게 대응하지 않으면 에러로 이어질 가능성이 크다.

```jsx
// DOM에 button 요소가 존재하지 않으면 querySelector 메서드는 에러를 발생시키지 않고 null을 반환한다.
const $button = document.querySelector('button'); // null

$button.classList.add('disabled');
// TypeError: Cannot read property 'classList' of null
```

위 예제의 querySelector 메서드는 인수로 전달한 문자열의 CSS 선택자 문법에 맞지 않는 경우 에러를 발생시킨다.

```jsx
const $elem = document.querySelector('#1');
// DOMException: Failed to execute 'querySelector' on 'Document': '#1' is not a valid selector.
```

하지만 querySelector 메서드는 인수로 전달한 CSS 선택자 문자열로 DOM에서 요소 노드를 찾을 수 없는 경우 에러를 발생시키지 않고 null 을 반환한다.

```jsx
// DOM에 button 요소가 존재하는 경우 querySelector 메서드는 에러를 발생시키지 않고 null을 반환한다.
const $button = document.querySelector('button'); // null
$button?.classList.add('disabled');
```

에러를 예외적인 상황에 대응하지 않으면 프로그램은 강제 종료될 것이다. 에러나 예외적인 상황은 너무나 다양하기 때문에 아무런 조치 없이 프로그램이 강제 종료된다면 원인을 파악하여 대응하기 어렵다.

에러가 발생하지 않는 코드를 작성하는 것이 이상적이지만 안타깝게도 그것은 불가능하다. 따라서 우리가 작성한 코드에서는 언제나 에러나 예외적인 상황이 발생할 수 있다는 것을 전제하고 이에 대응하는 코드를 작성하는 것이 중요하다.

## 47.2 try ... catch ... finally 문

기본적으로 에러 처리를 구현하는 방법은 크게 두가지가 있다. querySelector 이나 Array#find 메서드처럼 에외적인 사오항이 발생하면 반환하는 값을 if문이나 단축 평가 또는 옵셔널 체이닝 연산자를 통해 확인해서 처리하는 방법과 에러 처리 코드를 미리 등록해 두고 에러가 발생하면 에러 처리 코드로 점프하도록 하는 방법이 있다.

finally 문은 생략할수 있으나, catch 문도 생략이 가능하나. 이러면 try를 사용하는 이유가 없으므로, try , catch는 무조건 쓰인다.

```jsx
console.log('[Start]');

try {
  // 실행할 코드(에러가 발생할 가능성이 있는 코드)
  foo();
} catch (err) {
  // try 코드 블록에서 에러가 발생하면 이 코드 블록의 코드가 실행된다.
  // err에는 try 코드 블록에서 발생한 Error 객체가 전달된다.
  console.error(err); // ReferenceError: foo is not defined
} finally {
  // 에러 발생과 상관없이 반드시 한 번 실행된다.
  console.log('finally');
}

// try...catch...finally 문으로 에러를 처리하면 프로그램이 강제 종료되지 않는다.
console.log('[End]');
```

## 47.3 Error 객체

Error 생성자 함수는 에러 객체를 생성한다. Error 생성자 함수에는 에러를 상세히 설명하는 에러 메시지를 인수로 전달할 수 있다. 

```jsx
const error = new Error('invalid');
```

Error 생성자 함수가 생성한 에러 객체는 message 프로퍼티와 stack 프로퍼티를 갖는다. message 프로퍼티의 값은 Error 생성자 함수에 인수로 전달한 에러 메시지 이고, stack 프로퍼티 값은 에러를 발생시킨 콜스택의 호출 정보를 나타내는 문자열이며 디버깅 목적으로 사용한다.

자바스크립트는 Error 생성자 함수를 포함해 7가지의 에러 객체를 생성할 수 있는 Error 생성자 함수를 제공한다. 

| 생성자 함수 | 인스턴스 |
| --- | --- |
| Error | 일반적인 에러 객체 |
| SyntaxError | 자바스크립트 문법에 맞지 않는 문을 해석할 때 발생하는 에러 객체 |
| ReferenceError | 참조할 수 없는 식별자를 참조했을 때 발생하는 에러 객체 |
| RangeError | 피연산자 또는 인수의 데이터 타입이 유효하지 않을 때 발생하는 에러 객체 |
| URIError | encodeURI 또는 decodeURI 함수에 부적절한 인수를 전달했을 때 발생하는 에러 객체 |
| EvalError | eval 함수에는 발생하는 에러 객체 |

```jsx
1 @ 1;    // SyntaxError: Invalid or unexpected token
foo();    // ReferenceError: foo is not defined
null.foo; // TypeError: Cannot read property 'foo' of null
new Array(-1); // RangeError: Invalid array length
decodeURIComponent('%'); // URIError: URI malformed
```

## 47.4 throw 문

Error 생성자 함수로 에러 객체를 생성한다고 에러가 발생하는 것은 아니다. 즉 에러 객체 생성과 에러 발생은 의미가 다르다.

```jsx
try {
  // 에러 객체를 생성한다고 에러가 발생하는 것은 아니다.
  new Error('something wrong');
} catch (error) {
  console.log(error);
}
```

에러를 발생시키려면 try 코드 블록에서 throw 문으로 에러 객체를 던저야 한다.

throw 문의 표현식은 어떤 값이라도 상관없지만 일반적으로 에러 객체를 지정한다. 에러를 던지면 catch 문의 에러 변수가 생성되고 던져진 에러 객체가 할당된다. 그리고 catch 코드 블록이 실행되기 시작한다.

```jsx
try {
  // 에러 객체를 던지면 catch 코드 블록이 실행되기 시작한다.
  throw new Error('something wrong');
} catch (error) {
  console.log(error);
}
```

외부에서 전달받은 콜백 함수를 n번만큼 반복 호출하는 repeat 함수를 구현해 보자. repeat 함수는 두 번째 인수로 반드시 콜백 함수를 전달받아야 한다. 만약 두 번째 인수가 아니면 TypeError를 발생시킨다. repeat 함수는 에러를 발생시킬 가능성이 잇으므로 try 코드 블록 내부에서 호출해야한다.

```jsx
// 외부에서 전달받은 콜백 함수를 n번만큼 반복 호출한다
const repeat = (n, f) => {
  // 매개변수 f에 전달된 인수가 함수가 아니면 TypeError를 발생시킨다.
  if (typeof f !== 'function') throw new TypeError('f must be a function');

  for (var i = 0; i < n; i++) {
    f(i); // i를 전달하면서 f를 호출
  }
};

try {
  repeat(2, 1); // 두 번째 인수가 함수가 아니므로 TypeError가 발생(throw)한다.
} catch (err) {
  console.error(err); // TypeError: f must be a function
}
```

## 47.5 에러의 전파

에러는 호출자 방향으로 전파된다. 즉 콜 스택의 아래 방향으로 전파된다.

```jsx
const foo = () => {
  throw Error('foo에서 발생한 에러'); // ④
};

const bar = () => {
  foo(); // ③
};

const baz = () => {
  bar(); // ②
};

try {
  baz(); // ①
} catch (err) {
  console.error(err);
}
```

throw 에러를 캐치하지 않으면 호출잘 방향으로 전파되기에 이때 throw 된 에러를 캐치하여 적절히 대응하면 프로그램을 강제 종료시키지 않고 코드의 실행 흐름을 복구 할 수 있다. throw된 에러를 어디에서도 캐치하지 않으면 프로그램은 강제 종료된다.

주의할 것은 비동기 함수인 setTimeout 이나 프로미스 후속 처리 메서드의 콜백 함수는 호출자가 없다는 것이다. setTimeout 이나 프로미스 후속 처리 메서드의 콜백 함수는 태스크 큐나 마이크로태스크 큐에 일시 저장되었다가 콜 스택이 비면 이벤트 루프에 의해 콜 스택으로 푸시되어 실행된다. 이때 콜 스택에 푸시된 콜백 함수의 실행 컨텍스트는 콜 스택의 가장 하부에 존재하게 된다. 따라서 에러르 전파할 호출자가 존재하지 않는다.

# 알았거나 몰랐거나 알게된점

# **에러 처리**

- 에러가 발생하지 않는 코드를 작성하는 것은 불가능 하고, 에러 발생시 프로그램은 강제 종료 됨
- try...catch 문을 통해서 프로그램 강제 종료를 막을 수 있음
- **`예외 처리`** : 직접적으로 에러를 발생하지는 않는 상황
    - 예외적인 상황에 의해서 다른 코드가 에러를 발생할 수 있음
    - 예) querySelector의 경우 없으면 null을 반환함 -> null을 할당 받은 변수에 프로퍼티를 참조하여 사용하는 경우 error 발생
        - querySelector의 반환 값을 단축 평가 또는 옵셔널 체이닝 연산자 사용해 예외 처리 하거나, 에러 처리 코드를 미리 등록해 두고 에러 발생시 에러 처리 코드로 점프 되도록 하는 방법

## **try...catch...finally 문**

- 에러 처리(error handling) : try...catch...finally 문을 사용하여 에러를 처리하는 것
    - try : 에러가 발생할 가능성이 있는 코드 블럭
    - catch : try에서 에러 발생시 실행되는 코드 블럭 (try에서 발생한 Error 객체가 전달됨)
    - finally : 에러 발생과 상관 없이 반드시 한번 실행되는 코드 블럭

## **Error 객체**

- **`new Error(errorMessage)`**
    - errorMessage: 에러를 상세히 설명하는 에러 메세지(string)를 인수로 받음
- **`message 프로퍼티`** : Error 생성자 함수에 전달한 인수를 값으로 갖는 프로퍼티
- **`stack 프로퍼티`** : 에러를 발생시킨 콜스택의 호출 정보를 나타내는 문자열 (디버깅 목적)
- **`에러 객체 종류 7가지`**
    - Error : 일반적인 에러 객체
    - SyntaxError : JS 문법에 맞지 않는 문 해석시 발생하는 에러 객체
    - ReferenceError : 참조 함수 없는 식별자를 참조시 발생하는 에러 객체
    - TypeError : 피연산자 또는 인수의 데이터 타입이 유효하지 않을 때
    - RangeError : 숫자값의 허용 범위를 벗어났을 때 발생
    - URIError : encodeURI 또는 decodeURI 함수에 부적절한 인수 전달시 발생
    - EvalError : eval 함수에서 발생하는 에러 객체

## **thorw 문**

- 해당 에러 객체로 에러를 발생 시킴
- try 문에 error 발생시, catch 문에 error 변수가 생성되고 해당 error 객체가 할당됨

## **에러 전파**

- throw된 에러를 캐치 하지 않으면, 에러는 호출자 방향으로 전파 됨 (콜 스택의 아래 방향으로 전파됨)
- **비동기 함수, 프로미스 후속 처리 메서드의 콜백 함수는 호출자가 없기 때문에 에러 전파가 되지 않음**
