# [JavaScript] 47장 에러처리

# 47.1 에러 처리의 필요성

에러가 발생하지 않는 코드를 작성하는 것은 불가능하다. 따라서 에러에 대해 대처해야 한다.

# 47.2 try...catch...finally 문

에러 처리를 구현하는 방법은 두가지가 있다.

querySelector 나 Array#find 메서드처럼 예외적인 상황이 발생하면 반환하는 값(Null 또는 -1)을 If문이나 단축 평가 또는 옵셔널 체이닝을 통해 확인해서 처리하는 방법이 있고,
에러 처리 코드를 미리 등록해 두고 에러가 발생하면 에러 처리 코드로 점프하도록 하는 방법이 있다.

`try...catch...finally` 문은 두번째 방법이다. 일반적으로 이 방법을 에러 핸들링이라 한다.

`try...catch...finally` 문은 다음과 같이 3개의 코드 블록으로 구성되며, `finally` 문은 생략 가능하다.
( catch 문도 생략 가능하지만 catch 문을 생략하면 try 문 자체도 의미가 없다 ) 

```jsx
try {
	// 실행할 코드(에러가 발생할 가능성이 있는 코드)
} catch(err) {
	// try 코드 내에서 에러가 발생하면 이 코드 블록의 코드가 실행된다.
	// err 에는 try 코드 블록에서 발생한 Error 객체가 전달된다.
} finally {
	// 에러 발생과 상관없이 반드시 한 번 실행된다.
}
```

# 47.3 Error 객체

Error 생성자 함수는 에러 객체를 생성한다. Error 생성자 함수에는 에러를 상세히 설명하는 에러 메시지를 인수로 전달할 수 있다.

```jsx
const error = new Error('invalid')
```

Error 생성자 함수가 생성한 에러 객체는 message 프로퍼티와 stack 프로퍼티를 갖는다.

message 프로퍼티의 값은 Error 생성자 함수에 인수로 전달한 에러 메시지이고,
stack 프로퍼티의 값은 에럴르 발생시킨 콜 스택의 호출 정보를 나타내는 문자열이며 디버깅 목적으로 사용된다.

자바스크립트는 Error 생성자 함수를 포함해 7가지의 에러 객체를 생성할 수 있는 Error 생성자 함수를 제공한다.

| 생성자 함수 | 인스턴스 |
| --- | --- |
| Error | 일반적 에러 객체 |
| SyntaxError | 자바스크립트 문법에 맞지 않는 문을 해석할 때 발생하는 에러 객체 |
| ReferenceError | 참조할 수 없는 식별자를 참조했을 때 발생하는 에러 객체 |
| TypeError | 피연산자 또는 인수의 데이터 타입이 유효하지 않을 때 발생하는 에러 객체 |
| RangeError | 숫자값의 허용 범위를 벗어낫을 때 발생하는 에러 객체 |
| URIError | encodeURI 또는 decodeURI 함수에 부적절한 인수를 전달했을 때 발생하는 에러 객체 |
| EvalError | eval 함수에서 발생하는 에러 객체 |

# 47.4 throw 문

Error 생성자 함수로 에러 객체를 생성한다고 에러가 발생하는 것은 아니다.
즉, 에러 객체 생성과 에러 발생은 의미가 다르다.

```jsx
try {
	// 에러 객체를 생성한다고 에러가 발생하는 것은 아니다.
	new Error('something wrong')
} catch(error) {
	console.log(error)
}
```

에러를 발생시키려면 try 코드 블록에서 `throw` 문으로 에러 객체를 던져야 한다.

```jsx
throw 표현식
```

`throw` 문의 표현식은 어떤 값이라도 상관없지만 일반적으로 에러 객체를 지정한다.
에러를 던지면 catch 문의 에러 변수가 생성되고 던져진 에러 객체가 할당된다. 그리고 catch 코드 블록이 실행된다.

```jsx
try {
	throw new Error('something wrong')
} catch(error) {
	console.log(error)
}
```

# 47.5 에러의 전파

45장 “프로미스"의 45.1.2절 “에러 처리의 한계"에서 살펴본 바와 같이 에러는 호출자(caller) 방향으로 전파된다.
즉, 콜 스택의 아래 방향으로 전파된다.

```jsx
const foo = () => {
	throw new Error('foo에서 발생한 에러')
}

const bar = () => {
	foo()
}

const baz = () => {
	bar()
}

try {
	baz()
} catch(err) {
	console.error(err)
}
```

foo 함수는 bar 에서 호출되고, bar 는 baz 에서 호출되며, 이때 foo 함수가 throw 한 에러는 foo 실행 컨텍스트 → bar 실행 컨텍스트 → baz 실행 컨텍스트 → 전역 컨텍스트 순으로 에러가 전파된다.

throw 된 에러를 어디에서도 캐치하지 않으면 프로그램은 강제 종료된다.

**주의할 것은 비동기 함수인 setTimeout 이나 프로미스의 후속 처리 메서드의 콜백 함수는 호출자가 없다는 것이다.**

setTimeout 이나 프로미스 후속 처리 메서드의 콜백 함수는 태스크 큐나 마이크로태스크 큐에 일시 저장되었다가 콜 스택이 비면 이벤트 루프에 의해 콜 스택으로 푸시되어 실행된다. 이 때 콜스택으로 푸시된 콜백 함수의 실행 컨텍스트는 콜 스택의 가장 하부에 존재하게 된다. 따라서 에러를 전파할 호출자가 존재하지 않는다.